<?xml version="1.0"?>
<robot name="sample_robot">
  
  <!-- Base Link -->
  <link name="base_link">
    <visual>
      <geometry>
        <box size="0.2 0.2 0.1"/>
      </geometry>
      <material name="blue">
        <color rgba="0 0 1 1"/>
      </material>
    </visual>
    <collision>
      <geometry>
        <box size="0.2 0.2 0.1"/>
      </geometry>
    </collision>
    <inertial>
      <mass value="1.0"/>
      <inertia ixx="0.1" ixy="0" ixz="0" iyy="0.1" iyz="0" izz="0.1"/>
    </inertial>
  </link>

  <!-- Upper Link -->
  <link name="upper_link">
    <visual>
      <geometry>
        <cylinder radius="0.02" length="0.3"/>
      </geometry>
      <material name="red">
        <color rgba="1 0 0 1"/>
      </material>
    </visual>
    <collision>
      <geometry>
        <cylinder radius="0.02" length="0.3"/>
      </geometry>
    </collision>
    <inertial>
      <mass value="0.5"/>
      <inertia ixx="0.01" ixy="0" ixz="0" iyy="0.01" iyz="0" izz="0.001"/>
    </inertial>
  </link>

  <!-- Joint -->
  <joint name="base_to_upper" type="revolute">
    <parent link="base_link"/>
    <child link="upper_link"/>
    <origin xyz="0 0 0.1" rpy="0 0 0"/>
    <axis xyz="0 0 1"/>
    <limit lower="-3.14159" upper="3.14159" effort="10" velocity="1"/>
  </joint>

  <!-- Gazebo plugin for control -->
  <gazebo>
    <plugin name="gazebo_ros_control" filename="libgazebo_ros_control.so">
      <robotNamespace>/sample_robot</robotNamespace>
    </plugin>
  </gazebo>

  <!-- Link colors for Gazebo -->
  <gazebo reference="base_link">
    <material>Gazebo/Blue</material>
  </gazebo>

  <gazebo reference="upper_link">
    <material>Gazebo/Red</material>
  </gazebo>

</robot>